<?xml version="1.0" ?>
<robot name="UR5e_Lab2">
    <joint name="2F85_Opened_20190924_1_to_grabber_tcp" type="fixed">
        <origin xyz="5.2664e-14 0.113269 0.0934257" rpy="-1.5708 -3.61999e-06 1.31047e-11" />
        <parent link="2F85_Opened_20190924_1" />
        <child link="grabber_tcp" />
    </joint>
    <joint name="Robot1_base_to_front_center" type="fixed">
        <origin xyz="0.907616 -0.133362 0.0447653" rpy="1.57105 -3.14158 1.57062" />
        <parent link="Robot1_base" />
        <child link="front_center" />
    </joint>
    <joint name="Robot1_base_to_front_left" type="fixed">
        <origin xyz="0.907705 0.36664 0.0447522" rpy="1.57104 -3.14158 1.57064" />
        <parent link="Robot1_base" />
        <child link="front_left" />
    </joint>
    <joint name="Robot1_base_to_front_right" type="fixed">
        <origin xyz="0.907573 -0.333359 0.0447702" rpy="1.57106 -3.14158 1.57061" />
        <parent link="Robot1_base" />
        <child link="front_right" />
    </joint>
    <joint name="Robot1_base_to_front_staging" type="fixed">
        <origin xyz="0.919197 -0.1333 0.487859" rpy="1.57082 -3.14159 1.57079" />
        <parent link="Robot1_base" />
        <child link="front_staging" />
    </joint>
    <joint name="Robot1_base_to_low_center" type="fixed">
        <origin xyz="0.507605 -0.133299 0.0446698" rpy="1.5708 -3.14159 1.5708" />
        <parent link="Robot1_base" />
        <child link="low_center" />
    </joint>
    <joint name="Robot1_base_to_low_left" type="fixed">
        <origin xyz="0.507712 0.366704 0.0446612" rpy="1.57101 -3.14158 1.57065" />
        <parent link="Robot1_base" />
        <child link="low_left" />
    </joint>
    <joint name="Robot1_base_to_low_right" type="fixed">
        <origin xyz="0.507619 -0.333295 0.0446622" rpy="1.57093 -3.14158 1.57071" />
        <parent link="Robot1_base" />
        <child link="low_right" />
    </joint>
    <joint name="Robot1_base_to_staging" type="fixed">
        <origin xyz="0.619201 -0.133301 0.487849" rpy="1.57079 -3.14159 1.5708" />
        <parent link="Robot1_base" />
        <child link="staging" />
    </joint>
    <joint name="Robot1_base_to_top" type="fixed">
        <origin xyz="0.219202 -0.133315 0.787856" rpy="1.57078 3.14159 1.57084" />
        <parent link="Robot1_base" />
        <child link="top" />
    </joint>
    <joint name="Robot1_default_tcp-to-rtr_flange" type="fixed">
        <origin xyz="0 0 0" rpy="3.14159 -3.14159 1.5708" />
        <parent link="Robot1_default_tcp" />
        <child link="Robot1_rtr_flange" />
    </joint>
    <joint name="Robot1_elbow_joint" type="revolute">
        <axis xyz="0 0 1" />
        <limit lower="-3.141593" upper="3.141593" effort="1" velocity="3.141593" acceleration="5.235988" jerk="50.000000" />
        <origin xyz="-0.425 0 0" rpy="0 -0 0" />
        <parent link="Robot1_upper_arm" />
        <child link="Robot1_forearm" />
    </joint>
    <joint name="Robot1_shoulder_lift_joint" type="revolute">
        <axis xyz="0 0 1" />
        <limit lower="-6.283185" upper="6.283185" effort="1" velocity="3.141593" acceleration="5.235988" jerk="50.000000" />
        <origin xyz="0 0 0.1625" rpy="1.5708 -0 0" />
        <parent link="Robot1_shoulder" />
        <child link="Robot1_upper_arm" />
    </joint>
    <joint name="Robot1_shoulder_pan_joint" type="revolute">
        <axis xyz="0 0 1" />
        <limit lower="-6.283185" upper="6.283185" effort="1" velocity="3.141593" acceleration="5.235988" jerk="50.000000" />
        <origin xyz="0 0 0" rpy="0 -0 0" />
        <parent link="Robot1_base" />
        <child link="Robot1_shoulder" />
    </joint>
    <joint name="Robot1_wrist_1_joint" type="revolute">
        <axis xyz="0 0 1" />
        <limit lower="-6.283185" upper="6.283185" effort="1" velocity="3.141593" acceleration="5.235988" jerk="50.000000" />
        <origin xyz="-0.3922 0 0" rpy="0 -0 0" />
        <parent link="Robot1_forearm" />
        <child link="Robot1_wrist_1" />
    </joint>
    <joint name="Robot1_wrist_2_joint" type="revolute">
        <axis xyz="0 0 1" />
        <limit lower="-6.283185" upper="6.283185" effort="1" velocity="3.141593" acceleration="5.235988" jerk="50.000000" />
        <origin xyz="0 0 0.1333" rpy="1.5708 -0 0" />
        <parent link="Robot1_wrist_1" />
        <child link="Robot1_wrist_2" />
    </joint>
    <joint name="Robot1_wrist_3-to-default_tcp" type="fixed">
        <origin xyz="0 0 0.0996" rpy="0 -0 0" />
        <parent link="Robot1_wrist_3" />
        <child link="Robot1_default_tcp" />
    </joint>
    <joint name="Robot1_wrist_3_joint" type="revolute">
        <axis xyz="0 0 1" />
        <limit lower="-6.283185" upper="6.283185" effort="1" velocity="3.141593" acceleration="5.235988" jerk="50.000000" />
        <origin xyz="0 0 0.0997" rpy="-1.5708 -0 0" />
        <parent link="Robot1_wrist_2" />
        <child link="Robot1_wrist_3" />
    </joint>
    <joint name="back_wall_to_world" type="fixed">
        <origin xyz="-1.143 0.8382 -0.800095" rpy="3.14159 3.14159 1.5708" />
        <parent link="mounting" />
        <child link="back_wall" />
    </joint>
    <joint name="coupling_to_robot" type="fixed">
        <origin xyz="-0.000728247 -0.0897079 0.0985249" rpy="1.5708 6.50869e-15 3.14159" />
        <parent link="Robot1_wrist_3" />
        <child link="GRP-ES-CPL-062_20180810_1" />
    </joint>
    <joint name="gripper_to_coupling" type="fixed">
        <origin xyz="-0.000727637 0.015206 0.183084" rpy="3.14159 -3.61999e-06 3.14159" />
        <parent link="GRP-ES-CPL-062_20180810_1" />
        <child link="2F85_Opened_20190924_1" />
    </joint>
    <joint name="mounting_to_world" type="fixed">
        <origin xyz="0 0 0" rpy="0 -0 0" />
        <parent link="world" />
        <child link="mounting" />
    </joint>
    <joint name="robot_to_mounting" type="fixed">
        <origin xyz="0.127 0.127 0.0127" rpy="-1.31134e-07 4.95301e-23 3.61999e-06" />
        <parent link="mounting" />
        <child link="Robot1_base" />
    </joint>
    <joint name="stand_to_world" type="fixed">
        <origin xyz="0.127 0.127 -0.8001" rpy="8.74228e-08 -0 1.5708" />
        <parent link="mounting" />
        <child link="stand" />
    </joint>
    <joint name="table_to_world" type="fixed">
        <origin xyz="0.323848 -0.3302 -0.8001" rpy="-3.14159 -3.14159 3.14159" />
        <parent link="mounting" />
        <child link="table" />
    </joint>
    <link name="2F85_Opened_20190924_1">
        <violet>
            <geometry>
                <data filename="geometry/violet/2F85_Opened_20190924_1.vt" />
            </geometry>
        </violet>
        <dilated>
            <geometry>
                <mesh filename="geometry/dilated/2F85_Opened_20190924_1.dae" />
            </geometry>
            <dilation distance="0.015000" />
        </dilated>
        <visual>
            <geometry>
                <mesh filename="geometry/visual/2F85_Opened_20190924_1.dae" />
            </geometry>
        </visual>
        <collision>
            <geometry>
                <mesh filename="geometry/collision/2F85_Opened_20190924_1.dae" />
            </geometry>
        </collision>
    </link>
    <link name="GRP-ES-CPL-062_20180810_1">
        <violet>
            <geometry>
                <data filename="geometry/violet/GRP-ES-CPL-062_20180810_1.vt" />
            </geometry>
        </violet>
        <dilated>
            <geometry>
                <mesh filename="geometry/dilated/GRP-ES-CPL-062_20180810_1.dae" />
            </geometry>
            <dilation distance="0.015000" />
        </dilated>
        <visual>
            <geometry>
                <mesh filename="geometry/visual/GRP-ES-CPL-062_20180810_1.dae" />
            </geometry>
        </visual>
        <collision>
            <geometry>
                <mesh filename="geometry/collision/GRP-ES-CPL-062_20180810_1.dae" />
            </geometry>
        </collision>
    </link>
    <link name="Robot1_base">
        <cad>
            <geometry>
                <data filename="geometry/cad/Robot1_base.cdx" />
            </geometry>
        </cad>
        <violet>
            <geometry>
                <data filename="geometry/violet/Robot1_base.vt" />
            </geometry>
        </violet>
        <dilated>
            <geometry>
                <mesh filename="geometry/dilated/Robot1_base.dae" />
            </geometry>
            <dilation distance="0.000000" />
        </dilated>
        <visual>
            <geometry>
                <mesh filename="geometry/visual/Robot1_base.dae" />
            </geometry>
        </visual>
        <collision>
            <geometry>
                <mesh filename="geometry/collision/Robot1_base.dae" />
            </geometry>
        </collision>
    </link>
    <link name="Robot1_default_tcp" />
    <link name="Robot1_forearm">
        <cad>
            <geometry>
                <data filename="geometry/cad/Robot1_forearm.cdx" />
            </geometry>
        </cad>
        <violet>
            <geometry>
                <data filename="geometry/violet/Robot1_forearm.vt" />
            </geometry>
        </violet>
        <dilated>
            <geometry>
                <mesh filename="geometry/dilated/Robot1_forearm.dae" />
            </geometry>
            <dilation distance="0.015000" />
        </dilated>
        <visual>
            <geometry>
                <mesh filename="geometry/visual/Robot1_forearm.dae" />
            </geometry>
        </visual>
        <collision>
            <geometry>
                <mesh filename="geometry/collision/Robot1_forearm.dae" />
            </geometry>
        </collision>
    </link>
    <link name="Robot1_rtr_flange" />
    <link name="Robot1_shoulder">
        <cad>
            <geometry>
                <data filename="geometry/cad/Robot1_shoulder.cdx" />
            </geometry>
        </cad>
        <violet>
            <geometry>
                <data filename="geometry/violet/Robot1_shoulder.vt" />
            </geometry>
        </violet>
        <dilated>
            <geometry>
                <mesh filename="geometry/dilated/Robot1_shoulder.dae" />
            </geometry>
            <dilation distance="0.015000" />
        </dilated>
        <visual>
            <geometry>
                <mesh filename="geometry/visual/Robot1_shoulder.dae" />
            </geometry>
        </visual>
        <collision>
            <geometry>
                <mesh filename="geometry/collision/Robot1_shoulder.dae" />
            </geometry>
        </collision>
    </link>
    <link name="Robot1_upper_arm">
        <cad>
            <geometry>
                <data filename="geometry/cad/Robot1_upper_arm.cdx" />
            </geometry>
        </cad>
        <violet>
            <geometry>
                <data filename="geometry/violet/Robot1_upper_arm.vt" />
            </geometry>
        </violet>
        <dilated>
            <geometry>
                <mesh filename="geometry/dilated/Robot1_upper_arm.dae" />
            </geometry>
            <dilation distance="0.015000" />
        </dilated>
        <visual>
            <geometry>
                <mesh filename="geometry/visual/Robot1_upper_arm.dae" />
            </geometry>
        </visual>
        <collision>
            <geometry>
                <mesh filename="geometry/collision/Robot1_upper_arm.dae" />
            </geometry>
        </collision>
    </link>
    <link name="Robot1_wrist_1">
        <cad>
            <geometry>
                <data filename="geometry/cad/Robot1_wrist_1.cdx" />
            </geometry>
        </cad>
        <violet>
            <geometry>
                <data filename="geometry/violet/Robot1_wrist_1.vt" />
            </geometry>
        </violet>
        <dilated>
            <geometry>
                <mesh filename="geometry/dilated/Robot1_wrist_1.dae" />
            </geometry>
            <dilation distance="0.015000" />
        </dilated>
        <visual>
            <geometry>
                <mesh filename="geometry/visual/Robot1_wrist_1.dae" />
            </geometry>
        </visual>
        <collision>
            <geometry>
                <mesh filename="geometry/collision/Robot1_wrist_1.dae" />
            </geometry>
        </collision>
    </link>
    <link name="Robot1_wrist_2">
        <cad>
            <geometry>
                <data filename="geometry/cad/Robot1_wrist_2.cdx" />
            </geometry>
        </cad>
        <violet>
            <geometry>
                <data filename="geometry/violet/Robot1_wrist_2.vt" />
            </geometry>
        </violet>
        <dilated>
            <geometry>
                <mesh filename="geometry/dilated/Robot1_wrist_2.dae" />
            </geometry>
            <dilation distance="0.015000" />
        </dilated>
        <visual>
            <geometry>
                <mesh filename="geometry/visual/Robot1_wrist_2.dae" />
            </geometry>
        </visual>
        <collision>
            <geometry>
                <mesh filename="geometry/collision/Robot1_wrist_2.dae" />
            </geometry>
        </collision>
    </link>
    <link name="Robot1_wrist_3">
        <cad>
            <geometry>
                <data filename="geometry/cad/Robot1_wrist_3.cdx" />
            </geometry>
        </cad>
        <violet>
            <geometry>
                <data filename="geometry/violet/Robot1_wrist_3.vt" />
            </geometry>
        </violet>
        <dilated>
            <geometry>
                <mesh filename="geometry/dilated/Robot1_wrist_3.dae" />
            </geometry>
            <dilation distance="0.015000" />
        </dilated>
        <visual>
            <geometry>
                <mesh filename="geometry/visual/Robot1_wrist_3.dae" />
            </geometry>
        </visual>
        <collision>
            <geometry>
                <mesh filename="geometry/collision/Robot1_wrist_3.dae" />
            </geometry>
        </collision>
    </link>
    <link name="back_wall">
        <visual>
            <geometry>
                <mesh filename="geometry/visual/back_wall.dae" />
            </geometry>
        </visual>
        <collision>
            <geometry>
                <mesh filename="geometry/collision/back_wall.dae" />
            </geometry>
        </collision>
    </link>
    <link name="front_center" />
    <link name="front_left" />
    <link name="front_right" />
    <link name="front_staging" />
    <link name="grabber_tcp" />
    <link name="low_center" />
    <link name="low_left" />
    <link name="low_right" />
    <link name="mounting">
        <visual>
            <geometry>
                <mesh filename="geometry/visual/mounting.dae" />
            </geometry>
        </visual>
        <collision>
            <geometry>
                <mesh filename="geometry/collision/mounting.dae" />
            </geometry>
        </collision>
    </link>
    <link name="staging" />
    <link name="stand">
        <visual>
            <geometry>
                <mesh filename="geometry/visual/stand.dae" />
            </geometry>
        </visual>
        <collision>
            <geometry>
                <mesh filename="geometry/collision/stand.dae" />
            </geometry>
        </collision>
    </link>
    <link name="table">
        <visual>
            <geometry>
                <mesh filename="geometry/visual/table.dae" />
            </geometry>
        </visual>
        <collision>
            <geometry>
                <mesh filename="geometry/collision/table.dae" />
            </geometry>
        </collision>
    </link>
    <link name="top" />
    <link name="world" />
</robot>
